Workbook

Sheet Dashboard
A1: Overall Portfolio
A2: As of | B2: =OFFSET('Historical NAV'!A1,COUNT('Historical NAV'!B:B),,,) -> 45852
A3: Current Month | B3: =DATE(YEAR(B2), MONTH(B2), 1) -> 45839
A4: WTD | B4: =OFFSET('Historical NAV'!I1,COUNT('Historical NAV'!A:A),,,) -> -0.6851328
A5: MTD | B5: =OFFSET('Historical NAV'!K1,COUNT('Historical NAV'!A:A),,,) -> -0.68349276
A6: YTD | B6: =OFFSET('Historical NAV'!N1,COUNT('Historical NAV'!A:A),,,) -> -0.66335391
A8: Key Perf. Metrics | D8: Key Execution Metrics
A9: Daily Return | B9: =OFFSET('Historical NAV'!G1,COUNT('Historical NAV'!A:A),,,) -> -0.6851328 | D9: NAV (Net Liquidity) | E9: =OFFSET('Historical NAV'!B1,COUNT('Historical NAV'!A:A),,,) -> 20985069
A10: Leverage | B10: =E13/E9 -> 0.9961162 | D10: Excess Liquidity | E10: 41571526
A11: Return (30days) | B11: =OFFSET('Historical NAV'!R1,COUNT('Historical NAV'!A:A),,,) -> -0.67384436 | D11: Excess Liquidity/NAV | E11: =E10/E9 -> 1.9810049
A12: Return (90days) | B12: =OFFSET('Historical NAV'!T1,COUNT('Historical NAV'!A:A),,,) -> -0.74527735
A13: Return (365days) | B13: =OFFSET('Historical NAV'!V1,COUNT('Historical NAV'!A:A),,,) -> -0.3631342 | D13: To Allocate | E13: =K25 -> 20903567
A14: Sharpe Ratio | B14: =OFFSET('Historical NAV'!W1,COUNT('Historical NAV'!A:A),,,) -> -2.2529051 | D14: 0.005 | E14: =(D14*$E$13)/(1-D14) -> 105043.05
A15: Sotino Ratio | B15: =OFFSET('Historical NAV'!AB1,COUNT('Historical NAV'!A:A),,,) -> -0.33076595 | D15: 0.01 | E15: =(D15*$E$13)/(1-D15) -> 211147.14
A16: Volatility | B16: =OFFSET('Historical NAV'!P1,COUNT('Historical NAV'!A:A),,,) -> 1.8356923 | D16: 0.015 | E16: =(D16*$E$13)/(1-D16) -> 318328.44
A17: VaR 95% (30days) | B17: =OFFSET('Historical NAV'!AC1,COUNT('Historical NAV'!A:A),,,) -> -0.22973362 | D17: 0.05 | E17: =(D17*$E$13)/(1-D17) -> 1100187.8
A18: VaR 95% (90days) | B18: =OFFSET('Historical NAV'!AD1,COUNT('Historical NAV'!A:A),,,) -> -0.13175215
A19: VaR 95% (365days) | B19: =OFFSET('Historical NAV'!AE1,COUNT('Historical NAV'!A:A),,,) -> -0.077202934
A21: Performance by Asset Class
A23: Asset Class | B23: ETFs | C23: Stocks | D23: Stocks_int | E23: Bonds | F23: Commodities | G23: Future | H23: Option | I23: Crypto | J23: Others | K23: Total | L23: QQQ+TSM+NVDA | M23: Commodities | N23: gld
A24: No of investment | B24: =COUNTIF('Mark to Market'!$B$3:$B$1028,B23) -> 0 | C24: =COUNTIF('Mark to Market'!$B$3:$B$1028,C23) -> 0 | D24: =COUNTIF('Mark to Market'!$B$3:$B$1028,D23) -> 0 | E24: =COUNTIF('Mark to Market'!$B$3:$B$1028,E23) -> 1 | F24: =COUNTIF('Mark to Market'!$B$3:$B$1028,F23) -> 0 | G24: =COUNTIF('Mark to Market'!$B$3:$B$1028,G23) -> 0 | H24: =COUNTIF('Mark to Market'!$B$3:$B$1028,H23) -> 0 | I24: =COUNTIF('Mark to Market'!$B$3:$B$1028,I23) -> 0 | J24: =COUNTIF('Mark to Market'!$B$3:$B$1028,J23) -> 0 | K24: =SUM(B24:J24) -> 1 | L24: 3 | M24: 4
A25: Total Value (USD) | B25: =SUMIF('Mark to Market'!$B$3:$B$1028,B23,'Mark to Market'!$H$3:$H$1028) -> 0 | C25: =SUMIF('Mark to Market'!$B$3:$B$1028,C23,'Mark to Market'!$H$3:$H$1028) -> 0 | D25: =SUMIF('Mark to Market'!$B$3:$B$1028,D23,'Mark to Market'!$H$3:$H$1028) -> 0 | E25: =SUMIF('Mark to Market'!$B$3:$B$1028,E23,'Mark to Market'!$H$3:$H$1028) -> 20903567 | F25: =SUMIF('Mark to Market'!$B$3:$B$1028,F23,'Mark to Market'!$H$3:$H$1028) -> 0 | G25: =SUMIF('Mark to Market'!$B$3:$B$1028,G23,'Mark to Market'!$H$3:$H$1028) -> 0 | H25: =SUMIF('Mark to Market'!$B$3:$B$1028,H23,'Mark to Market'!$H$3:$H$1028) -> 0 | I25: =SUMIF('Mark to Market'!$B$3:$B$1028,I23,'Mark to Market'!$H$3:$H$1028) -> 0 | J25: =SUMIF('Mark to Market'!$B$3:$B$1028,J23,'Mark to Market'!$H$3:$H$1028) -> 0 | K25: =SUM(B25:J25) -> 20903567 | L25: =SUMIF('Mark to Market'!$A$3:$A$1028,"QQQ",'Mark to Market'!$H$3:$H$1028)+SUMIF('Mark to Market'!$A$3:$A$1028,"TSM",'Mark to Market'!$H$3:$H$1028)+SUMIF('Mark to Market'!$A$3:$A$1028,"NVDA",'Mark to Market'!$H$3:$H$1028) -> 0 | M25: =SUMIF('Mark to Market'!$B$3:$B$1028,M23,'Mark to Market'!$H$3:$H$1028)-(SUMIF('Mark to Market'!$A$3:$A$1028,"GLD",'Mark to Market'!$H$3:$H$1028)-SUMIF('Mark to Market'!$A$3:$A$1028,"IAUM",'Mark to Market'!$H$3:$H$1028))-SUMIF('Mark to Market'!$A$3:$A$1028,"2899",'Mark to Market'!$H$3:$H$1028) -> 0 | N25: =F25-M25 -> 0
A26: Total Weightage | B26: =B25/$K$25 -> 0 | C26: =C25/$K$25 -> 0 | D26: =D25/$K$25 -> 0 | E26: =E25/$K$25 -> 1 | F26: =F25/$K$25 -> 0 | G26: =G25/$K$25 -> 0 | H26: =H25/$K$25 -> 0 | I26: =I25/$K$25 -> 0 | J26: =J25/$K$25 -> 0 | K26: =SUM(B26:J26) -> 1 | L26: =L25/$K$25 -> 0 | M26: =M25/$K$25 -> 0 | N26: =F26-M26 -> 0
A27: Total Leverage | B27: =B25/$E$9 -> 0 | C27: =C25/$E$9 -> 0 | D27: =D25/$E$9 -> 0 | E27: =E25/$E$9 -> 0.9961162 | F27: =F25/$E$9 -> 0 | G27: =G25/$E$9 -> 0 | H27: =H25/$E$9 -> 0 | I27: =I25/$E$9 -> 0 | ... K27: =K25/$E$9 -> 0.9961162
A28: Target Allocation | L28: 0.35 | N28: 0.1
A29: Daily Return | B29: =OFFSET('Daily P&L breakdown'!B1,COUNT('Daily P&L breakdown'!$A:$A),,,) -> 0 | C29: =OFFSET('Daily P&L breakdown'!D1,COUNT('Daily P&L breakdown'!$A:$A),,,) -> 789.6 | D29: =OFFSET('Daily P&L breakdown'!C1,COUNT('Daily P&L breakdown'!$A:$A),,,) -> 0 | E29: =OFFSET('Daily P&L breakdown'!E1,COUNT('Daily P&L breakdown'!$A:$A),,,) -> 12500 | F29: =OFFSET('Daily P&L breakdown'!F1,COUNT('Daily P&L breakdown'!$A:$A),,,) -> 0 | G29: =OFFSET('Daily P&L breakdown'!G1,COUNT('Daily P&L breakdown'!$A:$A),,,) -> 0 | H29: =OFFSET('Daily P&L breakdown'!H1,COUNT('Daily P&L breakdown'!$A:$A),,,) -> 636.1 | I29: =OFFSET('Daily P&L breakdown'!I1,COUNT('Daily P&L breakdown'!$A:$A),,,) -> 0 | J29: =OFFSET('Daily P&L breakdown'!J1,COUNT('Daily P&L breakdown'!$A:$A),,,) -> 0 | K29: =SUM(B29:J29) -> 13925.7
A31: Monthly Attribution (Gross USD)
A32: Month | B32: ETFs | C32: Stocks | D32: Stocks_int | E32: Bonds | F32: Commodities | G32: Future | H32: Option | I32: Others | J32: Interest and Dividend | K32: Total | L32: checking
A33: 45658 | B33: =SUMIFS('Daily P&L breakdown'!B:B, 'Daily P&L breakdown'!$A:$A, ">=" & EOMONTH($A33, -1) + 1, 'Daily P&L breakdown'!$A:$A, "<=" & EOMONTH($A33, 0)) -> 1616679.8 | C33: =SUMIFS('Daily P&L breakdown'!D:D, 'Daily P&L breakdown'!$A:$A, ">=" & EOMONTH($A33, -1) + 1, 'Daily P&L breakdown'!$A:$A, "<=" & EOMONTH($A33, 0)) -> 227838.66 | D33: =SUMIFS('Daily P&L breakdown'!C:C, 'Daily P&L breakdown'!$A:$A, ">=" & EOMONTH($A33, -1) + 1, 'Daily P&L breakdown'!$A:$A, "<=" & EOMONTH($A33, 0)) -> 174582.75 | E33: =SUMIFS('Daily P&L breakdown'!E:E, 'Daily P&L breakdown'!$A:$A, ">=" & EOMONTH($A33, -1) + 1, 'Daily P&L breakdown'!$A:$A, "<=" & EOMONTH($A33, 0)) -> 149244.63 | F33: =SUMIFS('Daily P&L breakdown'!F:F, 'Daily P&L breakdown'!$A:$A, ">=" & EOMONTH($A33, -1) + 1, 'Daily P&L breakdown'!$A:$A, "<=" & EOMONTH($A33, 0)) -> 1307091.6 | G33: =SUMIFS('Daily P&L breakdown'!G:G, 'Daily P&L breakdown'!$A:$A, ">=" & EOMONTH($A33, -1) + 1, 'Daily P&L breakdown'!$A:$A, "<=" & EOMONTH($A33, 0)) -> 270528.75 | H33: =SUMIFS('Daily P&L breakdown'!H:H, 'Daily P&L breakdown'!$A:$A, ">=" & EOMONTH($A33, -1) + 1, 'Daily P&L breakdown'!$A:$A, "<=" & EOMONTH($A33, 0)) -> 894127.31 | I33: =SUMIFS('Daily P&L breakdown'!I:I, 'Daily P&L breakdown'!$A:$A, ">=" & EOMONTH($A33, -1) + 1, 'Daily P&L breakdown'!$A:$A, "<=" & EOMONTH($A33, 0)) -> 0 | K33: =SUM(B33:J33) -> 4640093.5 | L33: =SUM(Email!$T$9:$T$11)-K33 -> -4317812.9
A34: 45689 | B34: =SUMIFS('Daily P&L breakdown'!B:B, 'Daily P&L breakdown'!$A:$A, ">=" & EOMONTH($A34, -1) + 1, 'Daily P&L breakdown'!$A:$A, "<=" & EOMONTH($A34, 0)) -> 227.37 | C34: =SUMIFS('Daily P&L breakdown'!D:D, 'Daily P&L breakdown'!$A:$A, ">=" & EOMONTH($A34, -1) + 1, 'Daily P&L breakdown'!$A:$A, "<=" & EOMONTH($A34, 0)) -> 6715.93 | D34: =SUMIFS('Daily P&L breakdown'!C:C, 'Daily P&L breakdown'!$A:$A, ">=" & EOMONTH($A34, -1) + 1, 'Daily P&L breakdown'!$A:$A, "<=" & EOMONTH($A34, 0)) -> 0 | E34: =SUMIFS('Daily P&L breakdown'!E:E, 'Daily P&L breakdown'!$A:$A, ">=" & EOMONTH($A34, -1) + 1, 'Daily P&L breakdown'!$A:$A, "<=" & EOMONTH($A34, 0)) -> 286856.76 | F34: =SUMIFS('Daily P&L breakdown'!F:F, 'Daily P&L breakdown'!$A:$A, ">=" & EOMONTH($A34, -1) + 1, 'Daily P&L breakdown'!$A:$A, "<=" & EOMONTH($A34, 0)) -> 0 | G34: =SUMIFS('Daily P&L breakdown'!G:G, 'Daily P&L breakdown'!$A:$A, ">=" & EOMONTH($A34, -1) + 1, 'Daily P&L breakdown'!$A:$A, "<=" & EOMONTH($A34, 0)) -> 0 | H34: =SUMIFS('Daily P&L breakdown'!H:H, 'Daily P&L breakdown'!$A:$A, ">=" & EOMONTH($A34, -1) + 1, 'Daily P&L breakdown'!$A:$A, "<=" & EOMONTH($A34, 0)) -> 20303.14 | I34: =SUMIFS('Daily P&L breakdown'!I:I, 'Daily P&L breakdown'!$A:$A, ">=" & EOMONTH($A34, -1) + 1, 'Daily P&L breakdown'!$A:$A, "<=" & EOMONTH($A34, 0)) -> 0 | K34: =SUM(B34:J34) -> 314103.2
A35: 45717 | B35: =SUMIFS('Daily P&L breakdown'!B:B, 'Daily P&L breakdown'!$A:$A, ">=" & EOMONTH($A35, -1) + 1, 'Daily P&L breakdown'!$A:$A, "<=" & EOMONTH($A35, 0)) -> 0 | C35: =SUMIFS('Daily P&L breakdown'!D:D, 'Daily P&L breakdown'!$A:$A, ">=" & EOMONTH($A35, -1) + 1, 'Daily P&L breakdown'!$A:$A, "<=" & EOMONTH($A35, 0)) -> 0 | D35: =SUMIFS('Daily P&L breakdown'!C:C, 'Daily P&L breakdown'!$A:$A, ">=" & EOMONTH($A35, -1) + 1, 'Daily P&L breakdown'!$A:$A, "<=" & EOMONTH($A35, 0)) -> 0 | E35: =SUMIFS('Daily P&L breakdown'!E:E, 'Daily P&L breakdown'!$A:$A, ">=" & EOMONTH($A35, -1) + 1, 'Daily P&L breakdown'!$A:$A, "<=" & EOMONTH($A35, 0)) -> 0 | F35: =SUMIFS('Daily P&L breakdown'!F:F, 'Daily P&L breakdown'!$A:$A, ">=" & EOMONTH($A35, -1) + 1, 'Daily P&L breakdown'!$A:$A, "<=" & EOMONTH($A35, 0)) -> 0 | G35: =SUMIFS('Daily P&L breakdown'!G:G, 'Daily P&L breakdown'!$A:$A, ">=" & EOMONTH($A35, -1) + 1, 'Daily P&L breakdown'!$A:$A, "<=" & EOMONTH($A35, 0)) -> 0 | H35: =SUMIFS('Daily P&L breakdown'!H:H, 'Daily P&L breakdown'!$A:$A, ">=" & EOMONTH($A35, -1) + 1, 'Daily P&L breakdown'!$A:$A, "<=" & EOMONTH($A35, 0)) -> 0 | I35: =SUMIFS('Daily P&L breakdown'!I:I, 'Daily P&L breakdown'!$A:$A, ">=" & EOMONTH($A35, -1) + 1, 'Daily P&L breakdown'!$A:$A, "<=" & EOMONTH($A35, 0)) -> 0 | K35: =SUM(B35:J35) -> 0
A36: 45748 | B36: =SUMIFS('Daily P&L breakdown'!B:B, 'Daily P&L breakdown'!$A:$A, ">=" & EOMONTH($A36, -1) + 1, 'Daily P&L breakdown'!$A:$A, "<=" & EOMONTH($A36, 0)) -> 0 | C36: =SUMIFS('Daily P&L breakdown'!D:D, 'Daily P&L breakdown'!$A:$A, ">=" & EOMONTH($A36, -1) + 1, 'Daily P&L breakdown'!$A:$A, "<=" & EOMONTH($A36, 0)) -> 0 | D36: =SUMIFS('Daily P&L breakdown'!C:C, 'Daily P&L breakdown'!$A:$A, ">=" & EOMONTH($A36, -1) + 1, 'Daily P&L breakdown'!$A:$A, "<=" & EOMONTH($A36, 0)) -> 0 | E36: =SUMIFS('Daily P&L breakdown'!E:E, 'Daily P&L breakdown'!$A:$A, ">=" & EOMONTH($A36, -1) + 1, 'Daily P&L breakdown'!$A:$A, "<=" & EOMONTH($A36, 0)) -> 0 | F36: =SUMIFS('Daily P&L breakdown'!F:F, 'Daily P&L breakdown'!$A:$A, ">=" & EOMONTH($A36, -1) + 1, 'Daily P&L breakdown'!$A:$A, "<=" & EOMONTH($A36, 0)) -> 0 | G36: =SUMIFS('Daily P&L breakdown'!G:G, 'Daily P&L breakdown'!$A:$A, ">=" & EOMONTH($A36, -1) + 1, 'Daily P&L breakdown'!$A:$A, "<=" & EOMONTH($A36, 0)) -> 0 | H36: =SUMIFS('Daily P&L breakdown'!H:H, 'Daily P&L breakdown'!$A:$A, ">=" & EOMONTH($A36, -1) + 1, 'Daily P&L breakdown'!$A:$A, "<=" & EOMONTH($A36, 0)) -> 0 | I36: =SUMIFS('Daily P&L breakdown'!I:I, 'Daily P&L breakdown'!$A:$A, ">=" & EOMONTH($A36, -1) + 1, 'Daily P&L breakdown'!$A:$A, "<=" & EOMONTH($A36, 0)) -> 0 | K36: =SUM(B36:J36) -> 0
A37: 45778 | B37: =SUMIFS('Daily P&L breakdown'!B:B, 'Daily P&L breakdown'!$A:$A, ">=" & EOMONTH($A37, -1) + 1, 'Daily P&L breakdown'!$A:$A, "<=" & EOMONTH($A37, 0)) -> 0 | C37: =SUMIFS('Daily P&L breakdown'!D:D, 'Daily P&L breakdown'!$A:$A, ">=" & EOMONTH($A37, -1) + 1, 'Daily P&L breakdown'!$A:$A, "<=" & EOMONTH($A37, 0)) -> 0 | D37: =SUMIFS('Daily P&L breakdown'!C:C, 'Daily P&L breakdown'!$A:$A, ">=" & EOMONTH($A37, -1) + 1, 'Daily P&L breakdown'!$A:$A, "<=" & EOMONTH($A37, 0)) -> 0 | E37: =SUMIFS('Daily P&L breakdown'!E:E, 'Daily P&L breakdown'!$A:$A, ">=" & EOMONTH($A37, -1) + 1, 'Daily P&L breakdown'!$A:$A, "<=" & EOMONTH($A37, 0)) -> 0 | F37: =SUMIFS('Daily P&L breakdown'!F:F, 'Daily P&L breakdown'!$A:$A, ">=" & EOMONTH($A37, -1) + 1, 'Daily P&L breakdown'!$A:$A, "<=" & EOMONTH($A37, 0)) -> 0 | G37: =SUMIFS('Daily P&L breakdown'!G:G, 'Daily P&L breakdown'!$A:$A, ">=" & EOMONTH($A37, -1) + 1, 'Daily P&L breakdown'!$A:$A, "<=" & EOMONTH($A37, 0)) -> 0 | H37: =SUMIFS('Daily P&L breakdown'!H:H, 'Daily P&L breakdown'!$A:$A, ">=" & EOMONTH($A37, -1) + 1, 'Daily P&L breakdown'!$A:$A, "<=" & EOMONTH($A37, 0)) -> 0 | I37: =SUMIFS('Daily P&L breakdown'!I:I, 'Daily P&L breakdown'!$A:$A, ">=" & EOMONTH($A37, -1) + 1, 'Daily P&L breakdown'!$A:$A, "<=" & EOMONTH($A37, 0)) -> 0 | K37: =SUM(B37:J37) -> 0
A38: 45809 | B38: =SUMIFS('Daily P&L breakdown'!B:B, 'Daily P&L breakdown'!$A:$A, ">=" & EOMONTH($A38, -1) + 1, 'Daily P&L breakdown'!$A:$A, "<=" & EOMONTH($A38, 0)) -> 0 | C38: =SUMIFS('Daily P&L breakdown'!D:D, 'Daily P&L breakdown'!$A:$A, ">=" & EOMONTH($A38, -1) + 1, 'Daily P&L breakdown'!$A:$A, "<=" & EOMONTH($A38, 0)) -> 0 | D38: =SUMIFS('Daily P&L breakdown'!C:C, 'Daily P&L breakdown'!$A:$A, ">=" & EOMONTH($A38, -1) + 1, 'Daily P&L breakdown'!$A:$A, "<=" & EOMONTH($A38, 0)) -> 0 | E38: =SUMIFS('Daily P&L breakdown'!E:E, 'Daily P&L breakdown'!$A:$A, ">=" & EOMONTH($A38, -1) + 1, 'Daily P&L breakdown'!$A:$A, "<=" & EOMONTH($A38, 0)) -> 0 | F38: =SUMIFS('Daily P&L breakdown'!F:F, 'Daily P&L breakdown'!$A:$A, ">=" & EOMONTH($A38, -1) + 1, 'Daily P&L breakdown'!$A:$A, "<=" & EOMONTH($A38, 0)) -> 0 | G38: =SUMIFS('Daily P&L breakdown'!G:G, 'Daily P&L breakdown'!$A:$A, ">=" & EOMONTH($A38, -1) + 1, 'Daily P&L breakdown'!$A:$A, "<=" & EOMONTH($A38, 0)) -> 0 | H38: =SUMIFS('Daily P&L breakdown'!H:H, 'Daily P&L breakdown'!$A:$A, ">=" & EOMONTH($A38, -1) + 1, 'Daily P&L breakdown'!$A:$A, "<=" & EOMONTH($A38, 0)) -> 0 | I38: =SUMIFS('Daily P&L breakdown'!I:I, 'Daily P&L breakdown'!$A:$A, ">=" & EOMONTH($A38, -1) + 1, 'Daily P&L breakdown'!$A:$A, "<=" & EOMONTH($A38, 0)) -> 0 | K38: =SUM(B38:J38) -> 0
A39: 45839 | B39: =SUMIFS('Daily P&L breakdown'!B:B, 'Daily P&L breakdown'!$A:$A, ">=" & EOMONTH($A39, -1) + 1, 'Daily P&L breakdown'!$A:$A, "<=" & EOMONTH($A39, 0)) -> 0 | C39: =SUMIFS('Daily P&L breakdown'!D:D, 'Daily P&L breakdown'!$A:$A, ">=" & EOMONTH($A39, -1) + 1, 'Daily P&L breakdown'!$A:$A, "<=" & EOMONTH($A39, 0)) -> 0 | D39: =SUMIFS('Daily P&L breakdown'!C:C, 'Daily P&L breakdown'!$A:$A, ">=" & EOMONTH($A39, -1) + 1, 'Daily P&L breakdown'!$A:$A, "<=" & EOMONTH($A39, 0)) -> 0 | E39: =SUMIFS('Daily P&L breakdown'!E:E, 'Daily P&L breakdown'!$A:$A, ">=" & EOMONTH($A39, -1) + 1, 'Daily P&L breakdown'!$A:$A, "<=" & EOMONTH($A39, 0)) -> 0 | F39: =SUMIFS('Daily P&L breakdown'!F:F, 'Daily P&L breakdown'!$A:$A, ">=" & EOMONTH($A39, -1) + 1, 'Daily P&L breakdown'!$A:$A, "<=" & EOMONTH($A39, 0)) -> 0 | G39: =SUMIFS('Daily P&L breakdown'!G:G, 'Daily P&L breakdown'!$A:$A, ">=" & EOMONTH($A39, -1) + 1, 'Daily P&L breakdown'!$A:$A, "<=" & EOMONTH($A39, 0)) -> 0 | H39: =SUMIFS('Daily P&L breakdown'!H:H, 'Daily P&L breakdown'!$A:$A, ">=" & EOMONTH($A39, -1) + 1, 'Daily P&L breakdown'!$A:$A, "<=" & EOMONTH($A39, 0)) -> 0 | I39: =SUMIFS('Daily P&L breakdown'!I:I, 'Daily P&L breakdown'!$A:$A, ">=" & EOMONTH($A39, -1) + 1, 'Daily P&L breakdown'!$A:$A, "<=" & EOMONTH($A39, 0)) -> 0 | K39: =SUM(B39:J39) -> 0
A40: 45870 | B40: =SUMIFS('Daily P&L breakdown'!B:B, 'Daily P&L breakdown'!$A:$A, ">=" & EOMONTH($A40, -1) + 1, 'Daily P&L breakdown'!$A:$A, "<=" & EOMONTH($A40, 0)) -> 0 | C40: =SUMIFS('Daily P&L breakdown'!D:D, 'Daily P&L breakdown'!$A:$A, ">=" & EOMONTH($A40, -1) + 1, 'Daily P&L breakdown'!$A:$A, "<=" & EOMONTH($A40, 0)) -> 0 | D40: =SUMIFS('Daily P&L breakdown'!C:C, 'Daily P&L breakdown'!$A:$A, ">=" & EOMONTH($A40, -1) + 1, 'Daily P&L breakdown'!$A:$A, "<=" & EOMONTH($A40, 0)) -> 0 | E40: =SUMIFS('Daily P&L breakdown'!E:E, 'Daily P&L breakdown'!$A:$A, ">=" & EOMONTH($A40, -1) + 1, 'Daily P&L breakdown'!$A:$A, "<=" & EOMONTH($A40, 0)) -> 0 | F40: =SUMIFS('Daily P&L breakdown'!F:F, 'Daily P&L breakdown'!$A:$A, ">=" & EOMONTH($A40, -1) + 1, 'Daily P&L breakdown'!$A:$A, "<=" & EOMONTH($A40, 0)) -> 0 | G40: =SUMIFS('Daily P&L breakdown'!G:G, 'Daily P&L breakdown'!$A:$A, ">=" & EOMONTH($A40, -1) + 1, 'Daily P&L breakdown'!$A:$A, "<=" & EOMONTH($A40, 0)) -> 0 | H40: =SUMIFS('Daily P&L breakdown'!H:H, 'Daily P&L breakdown'!$A:$A, ">=" & EOMONTH($A40, -1) + 1, 'Daily P&L breakdown'!$A:$A, "<=" & EOMONTH($A40, 0)) -> 0 | I40: =SUMIFS('Daily P&L breakdown'!I:I, 'Daily P&L breakdown'!$A:$A, ">=" & EOMONTH($A40, -1) + 1, 'Daily P&L breakdown'!$A:$A, "<=" & EOMONTH($A40, 0)) -> 0 | K40: =SUM(B40:J40) -> 0
A41: 45901 | B41: =SUMIFS('Daily P&L breakdown'!B:B, 'Daily P&L breakdown'!$A:$A, ">=" & EOMONTH($A41, -1) + 1, 'Daily P&L breakdown'!$A:$A, "<=" & EOMONTH($A41, 0)) -> 0 | C41: =SUMIFS('Daily P&L breakdown'!D:D, 'Daily P&L breakdown'!$A:$A, ">=" & EOMONTH($A41, -1) + 1, 'Daily P&L breakdown'!$A:$A, "<=" & EOMONTH($A41, 0)) -> 0 | D41: =SUMIFS('Daily P&L breakdown'!C:C, 'Daily P&L breakdown'!$A:$A, ">=" & EOMONTH($A41, -1) + 1, 'Daily P&L breakdown'!$A:$A, "<=" & EOMONTH($A41, 0)) -> 0 | E41: =SUMIFS('Daily P&L breakdown'!E:E, 'Daily P&L breakdown'!$A:$A, ">=" & EOMONTH($A41, -1) + 1, 'Daily P&L breakdown'!$A:$A, "<=" & EOMONTH($A41, 0)) -> 0 | F41: =SUMIFS('Daily P&L breakdown'!F:F, 'Daily P&L breakdown'!$A:$A, ">=" & EOMONTH($A41, -1) + 1, 'Daily P&L breakdown'!$A:$A, "<=" & EOMONTH($A41, 0)) -> 0 | G41: =SUMIFS('Daily P&L breakdown'!G:G, 'Daily P&L breakdown'!$A:$A, ">=" & EOMONTH($A41, -1) + 1, 'Daily P&L breakdown'!$A:$A, "<=" & EOMONTH($A41, 0)) -> 0 | H41: =SUMIFS('Daily P&L breakdown'!H:H, 'Daily P&L breakdown'!$A:$A, ">=" & EOMONTH($A41, -1) + 1, 'Daily P&L breakdown'!$A:$A, "<=" & EOMONTH($A41, 0)) -> 0 | I41: =SUMIFS('Daily P&L breakdown'!I:I, 'Daily P&L breakdown'!$A:$A, ">=" & EOMONTH($A41, -1) + 1, 'Daily P&L breakdown'!$A:$A, "<=" & EOMONTH($A41, 0)) -> 0 | K41: =SUM(B41:J41) -> 0
A42: 45931 | B42: =SUMIFS('Daily P&L breakdown'!B:B, 'Daily P&L breakdown'!$A:$A, ">=" & EOMONTH($A42, -1) + 1, 'Daily P&L breakdown'!$A:$A, "<=" & EOMONTH($A42, 0)) -> 0 | C42: =SUMIFS('Daily P&L breakdown'!D:D, 'Daily P&L breakdown'!$A:$A, ">=" & EOMONTH($A42, -1) + 1, 'Daily P&L breakdown'!$A:$A, "<=" & EOMONTH($A42, 0)) -> 0 | D42: =SUMIFS('Daily P&L breakdown'!C:C, 'Daily P&L breakdown'!$A:$A, ">=" & EOMONTH($A42, -1) + 1, 'Daily P&L breakdown'!$A:$A, "<=" & EOMONTH($A42, 0)) -> 0 | E42: =SUMIFS('Daily P&L breakdown'!E:E, 'Daily P&L breakdown'!$A:$A, ">=" & EOMONTH($A42, -1) + 1, 'Daily P&L breakdown'!$A:$A, "<=" & EOMONTH($A42, 0)) -> 0 | F42: =SUMIFS('Daily P&L breakdown'!F:F, 'Daily P&L breakdown'!$A:$A, ">=" & EOMONTH($A42, -1) + 1, 'Daily P&L breakdown'!$A:$A, "<=" & EOMONTH($A42, 0)) -> 0 | G42: =SUMIFS('Daily P&L breakdown'!G:G, 'Daily P&L breakdown'!$A:$A, ">=" & EOMONTH($A42, -1) + 1, 'Daily P&L breakdown'!$A:$A, "<=" & EOMONTH($A42, 0)) -> 0 | H42: =SUMIFS('Daily P&L breakdown'!H:H, 'Daily P&L breakdown'!$A:$A, ">=" & EOMONTH($A42, -1) + 1, 'Daily P&L breakdown'!$A:$A, "<=" & EOMONTH($A42, 0)) -> 0 | I42: =SUMIFS('Daily P&L breakdown'!I:I, 'Daily P&L breakdown'!$A:$A, ">=" & EOMONTH($A42, -1) + 1, 'Daily P&L breakdown'!$A:$A, "<=" & EOMONTH($A42, 0)) -> 0 | K42: =SUM(B42:J42) -> 0
A43: 45962 | B43: =SUMIFS('Daily P&L breakdown'!B:B, 'Daily P&L breakdown'!$A:$A, ">=" & EOMONTH($A43, -1) + 1, 'Daily P&L breakdown'!$A:$A, "<=" & EOMONTH($A43, 0)) -> 0 | C43: =SUMIFS('Daily P&L breakdown'!D:D, 'Daily P&L breakdown'!$A:$A, ">=" & EOMONTH($A43, -1) + 1, 'Daily P&L breakdown'!$A:$A, "<=" & EOMONTH($A43, 0)) -> 0 | D43: =SUMIFS('Daily P&L breakdown'!C:C, 'Daily P&L breakdown'!$A:$A, ">=" & EOMONTH($A43, -1) + 1, 'Daily P&L breakdown'!$A:$A, "<=" & EOMONTH($A43, 0)) -> 0 | E43: =SUMIFS('Daily P&L breakdown'!E:E, 'Daily P&L breakdown'!$A:$A, ">=" & EOMONTH($A43, -1) + 1, 'Daily P&L breakdown'!$A:$A, "<=" & EOMONTH($A43, 0)) -> 0 | F43: =SUMIFS('Daily P&L breakdown'!F:F, 'Daily P&L breakdown'!$A:$A, ">=" & EOMONTH($A43, -1) + 1, 'Daily P&L breakdown'!$A:$A, "<=" & EOMONTH($A43, 0)) -> 0 | G43: =SUMIFS('Daily P&L breakdown'!G:G, 'Daily P&L breakdown'!$A:$A, ">=" & EOMONTH($A43, -1) + 1, 'Daily P&L breakdown'!$A:$A, "<=" & EOMONTH($A43, 0)) -> 0 | H43: =SUMIFS('Daily P&L breakdown'!H:H, 'Daily P&L breakdown'!$A:$A, ">=" & EOMONTH($A43, -1) + 1, 'Daily P&L breakdown'!$A:$A, "<=" & EOMONTH($A43, 0)) -> 0 | I43: =SUMIFS('Daily P&L breakdown'!I:I, 'Daily P&L breakdown'!$A:$A, ">=" & EOMONTH($A43, -1) + 1, 'Daily P&L breakdown'!$A:$A, "<=" & EOMONTH($A43, 0)) -> 0 | K43: =SUM(B43:J43) -> 0
A44: 45992 | B44: =SUMIFS('Daily P&L breakdown'!B:B, 'Daily P&L breakdown'!$A:$A, ">=" & EOMONTH($A44, -1) + 1, 'Daily P&L breakdown'!$A:$A, "<=" & EOMONTH($A44, 0)) -> 0 | C44: =SUMIFS('Daily P&L breakdown'!D:D, 'Daily P&L breakdown'!$A:$A, ">=" & EOMONTH($A44, -1) + 1, 'Daily P&L breakdown'!$A:$A, "<=" & EOMONTH($A44, 0)) -> 0 | D44: =SUMIFS('Daily P&L breakdown'!C:C, 'Daily P&L breakdown'!$A:$A, ">=" & EOMONTH($A44, -1) + 1, 'Daily P&L breakdown'!$A:$A, "<=" & EOMONTH($A44, 0)) -> 0 | E44: =SUMIFS('Daily P&L breakdown'!E:E, 'Daily P&L breakdown'!$A:$A, ">=" & EOMONTH($A44, -1) + 1, 'Daily P&L breakdown'!$A:$A, "<=" & EOMONTH($A44, 0)) -> 0 | F44: =SUMIFS('Daily P&L breakdown'!F:F, 'Daily P&L breakdown'!$A:$A, ">=" & EOMONTH($A44, -1) + 1, 'Daily P&L breakdown'!$A:$A, "<=" & EOMONTH($A44, 0)) -> 0 | G44: =SUMIFS('Daily P&L breakdown'!G:G, 'Daily P&L breakdown'!$A:$A, ">=" & EOMONTH($A44, -1) + 1, 'Daily P&L breakdown'!$A:$A, "<=" & EOMONTH($A44, 0)) -> 0 | H44: =SUMIFS('Daily P&L breakdown'!H:H, 'Daily P&L breakdown'!$A:$A, ">=" & EOMONTH($A44, -1) + 1, 'Daily P&L breakdown'!$A:$A, "<=" & EOMONTH($A44, 0)) -> 0 | I44: =SUMIFS('Daily P&L breakdown'!I:I, 'Daily P&L breakdown'!$A:$A, ">=" & EOMONTH($A44, -1) + 1, 'Daily P&L breakdown'!$A:$A, "<=" & EOMONTH($A44, 0)) -> 0 | K44: =SUM(B44:J44) -> 0
...

Sheet Historical NAV
A1: DATE | B1: NAV (USD) | C1: CASH INJECTION | D1: NEXT START NAV | E1: M START NAV | F1: DAILY P&L | G1: Daily Return | H1: Weekly P&L | I1: Weekly Return | J1: MTD Change | K1: MTD % | L1: Cal | M1: LTD ROR% | N1: YTD ROR% | O1: Annualised Return | P1: Annualised Volatility | Q1: 30 Days P&L | R1: 30 Days Return | S1: 90 Days P&L | T1: 90 Days Return | U1: 365 Days P&L | V1: 365 Days Return | W1: Sharpe Ratio | X1: Risk Free Rate (Assumed 4.5%) | Y1: Excess Return | Z1: Negative Excess Returns | AA1: Square of (Negative Excess Returns) | AB1: Sotino Ratio | AC1: Value at Risk 95%(30days) | AD1: Value at Risk 95%(90days) | AE1: Value at Risk 95%(365days)
A2: 44013 | B2: 8106215.1 | D2: 8106215.1 | E2: 8129676.1 | F2: -23460.98 | G2: -0.0028858444 | J2: -23460.98 | K2: -0.0028858444 | L2: =1+G2 -> 0.99711416 | M2: =PRODUCT($L$2:L2)-1 -> -0.0028858444 | N2: =PRODUCT($L2:L$2)-1 -> -0.0028858444 | O2: =AVERAGE($G2:G$2)*252 -> -0.72723278 | P2: =STDEV($G2:G$2)*252^0.5 -> #DIV/0!
A3: 44014 | B3: 8174039.8 | D3: =B3 -> 8174039.8 | E3: =E2 -> 8129676.1 | F3: 67824.64 | G3: 0.0083669924 | J3: 44363.66 | K3: 0.0054570021 | L3: =1+G3 -> 1.008367 | M3: =PRODUCT($L$2:L3)-1 -> 0.0054570021 | N3: =PRODUCT($L$2:L3)-1 -> 0.0054570021 | O3: =AVERAGE($G$2:G3)*252 -> 0.69062465 | P3: =STDEV($G$2:G3)*252^0.5 -> 0.12631278
A4: 44018 | B4: 8297117.3 | D4: =B4 -> 8297117.3 | E4: =E3 -> 8129676.1 | F4: 123077.55 | G4: 0.015057126 | J4: 167441.21 | K4: 0.020596295 | L4: =1+G4 -> 1.0150571 | M4: =PRODUCT($L$2:L4)-1 -> 0.020596295 | N4: =PRODUCT($L$2:L4)-1 -> 0.020596295 | O4: =AVERAGE($G$2:G4)*252 -> 1.725215 | P4: =STDEV($G$2:G4)*252^0.5 -> 0.14394459
A5: 44019 | B5: 8333268.5 | D5: =B5 -> 8333268.5 | E5: =E4 -> 8129676.1 | F5: 36151.23 | G5: 0.0043570831 | J5: 203592.44 | K5: 0.025043118 | L5: =1+G5 -> 1.0043571 | M5: =PRODUCT($L$2:L5)-1 -> 0.025043118 | N5: =PRODUCT($L$2:L5)-1 -> 0.025043118 | O5: =AVERAGE($G$2:G5)*252 -> 1.5684075 | P5: =STDEV($G$2:G5)*252^0.5 -> 0.11917911
A6: 44020 | B6: 8402868.6 | D6: =B6 -> 8402868.6 | E6: =E5 -> 8129676.1 | F6: 69600.06 | G6: 0.0083520721 | J6: 273192.5 | K6: 0.033604352 | L6: =1+G6 -> 1.0083521 | M6: =PRODUCT($L$2:L6)-1 -> 0.033604352 | N6: =PRODUCT($L$2:L6)-1 -> 0.033604352 | O6: =AVERAGE($G$2:G6)*252 -> 1.6756705 | P6: =STDEV($G$2:G6)*252^0.5 -> 0.10431215
A7: 44021 | B7: 8486246.5 | D7: =B7 -> 8486246.5 | E7: =E6 -> 8129676.1 | F7: 83377.92 | G7: 0.0099225543 | J7: 356570.42 | K7: 0.043860348 | L7: =1+G7 -> 1.0099226 | M7: =PRODUCT($L$2:L7)-1 -> 0.043860348 | N7: =PRODUCT($L$2:L7)-1 -> 0.043860348 | O7: =AVERAGE($G$2:G7)*252 -> 1.8131393 | P7: =STDEV($G$2:G7)*252^0.5 -> 0.095680536
A8: 44025 | B8: 8403900.2 | D8: =B8 -> 8403900.2 | E8: =E7 -> 8129676.1 | F8: -82346.35 | G8: -0.0097035067 | J8: 274224.07 | K8: 0.033731242 | L8: =1+G8 -> 0.99029649 | M8: =PRODUCT($L$2:L8)-1 -> 0.033731242 | N8: =PRODUCT($L$2:L8)-1 -> 0.033731242 | O8: =AVERAGE($G$2:G8)*252 -> 1.2047932 | P8: =STDEV($G$2:G8)*252^0.5 -> 0.13382492
A9: 44026 | B9: 8483233.3 | D9: =B9 -> 8483233.3 | E9: =E8 -> 8129676.1 | F9: 79333.16 | G9: 0.0094400407 | J9: 353557.23 | K9: 0.043489707 | L9: =1+G9 -> 1.00944 | M9: =PRODUCT($L$2:L9)-1 -> 0.043489707 | N9: =PRODUCT($L$2:L9)-1 -> 0.043489707 | O9: =AVERAGE($G$2:G9)*252 -> 1.3515553 | P9: =STDEV($G$2:G9)*252^0.5 -> 0.1266272
A10: 44027 | B10: 8478930.9 | D10: =B10 -> 8478930.9 | E10: =E9 -> 8129676.1 | F10: -4302.43 | G10: -0.00050716865 | J10: 349254.8 | K10: 0.042960481 | L10: =1+G10 -> 0.99949283 | M10: =PRODUCT($L$2:L10)-1 -> 0.042960481 | N10: =PRODUCT($L$2:L10)-1 -> 0.042960481 | O10: =AVERAGE($G$2:G10)*252 -> 1.1871818 | P10: =STDEV($G$2:G10)*252^0.5 -> 0.12245446
A11: 44028 | B11: 8434812.8 | D11: =B11 -> 8434812.8 | E11: =E9 -> 8129676.1 | F11: -44118.11 | G11: -0.0052006244 | J11: 305136.69 | K11: 0.037533683 | L11: =1+G11 -> 0.99479938 | M11: =PRODUCT($L$2:L11)-1 -> 0.037536436 | N11: =PRODUCT($L$2:L11)-1 -> 0.037536436 | O11: =AVERAGE($G$2:G11)*252 -> 0.93740787 | P11: =STDEV($G$2:G11)*252^0.5 -> 0.12571654
A12: 44029 | B12: 8475481.8 | D12: =B12 -> 8475481.8 | E12: =E11 -> 8129676.1 | F12: 40668.96 | G12: 0.0048215605 | J12: 345805.65 | K12: 0.042536215 | L12: =1+G12 -> 1.0048216 | M12: =PRODUCT($L$2:L12)-1 -> 0.04253898 | N12: =PRODUCT($L$2:L12)-1 -> 0.04253898 | O12: =AVERAGE($G$2:G12)*252 -> 0.96264654 | P12: =STDEV($G$2:G12)*252^0.5 -> 0.11938169
A13: 44032 | B13: 7795603.9 | C13: -800000 | D13: =B13 -> 7795603.9 | E13: =E12 -> 8129676.1 | F13: 120122.1 | G13: 0.0157 | J13: -334072.25 | K13: 0.0589 | L13: =1+G13 -> 1.0157 | M13: =PRODUCT($L$2:L13)-1 -> 0.058906842 | N13: =PRODUCT($L$2:L13)-1 -> 0.058906842 | O13: =AVERAGE($G$2:G13)*252 -> 1.212126 | P13: =STDEV($G$2:G13)*252^0.5 -> 0.12617512
A14: 44033 | B14: 7768360.5 | D14: =B14 -> 7768360.5 | E14: =E13+C13 -> 7329676.1 | F14: -27243.35 | G14: -0.0034947068 | J14: 438684.4 | K14: 0.0552 | L14: =1+G14 -> 0.99650529 | M14: =PRODUCT($L$2:L14)-1 -> 0.055206273 | N14: =PRODUCT($L$2:L14)-1 -> 0.055206273 | O14: =AVERAGE($G$2:G14)*252 -> 1.051142 | P14: =STDEV($G$2:G14)*252^0.5 -> 0.12621573
A15: 44034 | B15: 7803379.3 | D15: =B15 -> 7803379.3 | E15: =E14 -> 7329676.1 | F15: 35018.83 | G15: 0.0045078791 | J15: 473703.23 | K15: 0.0599 | L15: =1+G15 -> 1.0045079 | M15: =PRODUCT($L$2:L15)-1 -> 0.059963016 | N15: =PRODUCT($L$2:L15)-1 -> 0.059963016 | O15: =AVERAGE($G$2:G15)*252 -> 1.0572022 | P15: =STDEV($G$2:G15)*252^0.5 -> 0.12127256
A16: 44035 | B16: 7757505.2 | D16: =B16 -> 7757505.2 | E16: 7362157.3 | F16: -45874.16 | G16: -0.0058787556 | J16: 395347.85 | K16: 0.0537 | L16: =1+G16 -> 0.99412124 | M16: =PRODUCT($L$2:L16)-1 -> 0.053731752 | N16: =PRODUCT($L$2:L16)-1 -> 0.053731752 | O16: =AVERAGE($G$2:G16)*252 -> 0.887959 | P16: =STDEV($G$2:G16)*252^0.5 -> 0.12394147
A17: 44036 | B17: 7718043 | D17: =B17 -> 7718043 | E17: =E16 -> 7362157.3 | F17: -39462.22 | G17: -0.0050869731 | J17: 355885.63 | K17: 0.048339856 | L17: =1+G17 -> 0.99491303 | M17: =PRODUCT($L$2:L17)-1 -> 0.048371447 | N17: =PRODUCT($L$2:L17)-1 -> 0.048371447 | O17: =AVERAGE($G$2:G17)*252 -> 0.75234173 | P17: =STDEV($G$2:G17)*252^0.5 -> 0.12451963
A18: 44039 | B18: 7848768.5 | D18: =B18 -> 7848768.5 | E18: =E17 -> 7362157.3 | F18: 130725.52 | G18: 0.016937651 | J18: 486611.15 | K18: 0.066096271 | L18: =1+G18 -> 1.0169377 | M18: =PRODUCT($L$2:L18)-1 -> 0.066128397 | N18: =PRODUCT($L$2:L18)-1 -> 0.066128397 | O18: =AVERAGE($G$2:G18)*252 -> 0.95916211 | P18: =STDEV($G$2:G18)*252^0.5 -> 0.13199114
A19: 44040 | B19: 7829336.3 | D19: =B19 -> 7829336.3 | E19: =E18 -> 7362157.3 | F19: -19432.15 | G19: -0.0024758215 | J19: 467179 | K19: 0.0634 | L19: =1+G19 -> 0.99752418 | M19: =PRODUCT($L$2:L19)-1 -> 0.063488854 | N19: =PRODUCT($L$2:L19)-1 -> 0.063488854 | O19: =AVERAGE($G$2:G19)*252 -> 0.87121382 | P19: =STDEV($G$2:G19)*252^0.5 -> 0.13018967
A20: 44041 | B20: 7899344.2 | D20: =B20 -> 7899344.2 | E20: =E19 -> 7362157.3 | F20: 70007.84 | G20: 0.0089417336 | J20: 537186.84 | K20: 0.0729 | L20: =1+G20 -> 1.0089417 | M20: =PRODUCT($L$2:L20)-1 -> 0.072998288 | N20: =PRODUCT($L$2:L20)-1 -> 0.072998288 | O20: =AVERAGE($G$2:G20)*252 -> 0.94395609 | P20: =STDEV($G$2:G20)*252^0.5 -> 0.12808855
A21: 44043 | B21: 8019590.3 | D21: =B21 -> 8019590.3 | E21: =E20 -> 7362157.3 | F21: 120149.88 | G21: 0.015210108 | J21: 657336.72 | K21: 0.089285883 | L21: =1+G21 -> 1.0152101 | M21: =PRODUCT($L$2:L21)-1 -> 0.089318708 | N21: =PRODUCT($L$2:L21)-1 -> 0.089318708 | O21: =AVERAGE($G$2:G21)*252 -> 1.0884056 | P21: =STDEV($G$2:G21)*252^0.5 -> 0.13114562
A22: 44046 | B22: 8080929.5 | D22: =B22 -> 8080929.5 | E22: =IF(MONTH(A22)=MONTH(A21),E21,D21) -> 8019590.3 | F22: =B22-C22-D21 -> 61339.18 | G22: =F22/B21 -> 0.0076486675 | J22: =IF(MONTH(A22)=MONTH(A21),J21+F22,F22) -> 61339.18 | K22: =J22/E22 -> 0.0076486675 | L22: =1+G22 -> 1.0076487 | M22: =PRODUCT($L$2:L22)-1 -> 0.097650544 | N22: =PRODUCT($L$2:L22)-1 -> 0.097650544 | O22: =AVERAGE($G$2:G22)*252 -> 1.1283608 | P22: =STDEV($G$2:G22)*252^0.5 -> 0.12834426
A23: 44047 | B23: 8290234 | D23: =B23 -> 8290234 | E23: =IF(MONTH(A23)=MONTH(A22),E22,D22) -> 8019590.3 | F23: =B23-C23-D22 -> 209304.52 | G23: =F23/B22 -> 0.025901045 | J23: =IF(MONTH(A23)=MONTH(A22),J22+F23,F23) -> 270643.7 | K23: =J23/E23 -> 0.033747821 | L23: =1+G23 -> 1.025901 | M23: =PRODUCT($L$2:L23)-1 -> 0.12608084 | N23: =PRODUCT($L$2:L23)-1 -> 0.12608084 | O23: =AVERAGE($G$2:G23)*252 -> 1.3737564 | P23: =STDEV($G$2:G23)*252^0.5 -> 0.14472412
A24: 44048 | B24: 8397007.3 | D24: =B24 -> 8397007.3 | E24: =IF(MONTH(A24)=MONTH(A23),E23,D23) -> 8019590.3 | F24: =B24-C24-D23 -> 106773.3 | G24: =F24/B23 -> 0.012879407 | J24: =IF(MONTH(A24)=MONTH(A23),J23+F24,F24) -> 377417 | K24: =J24/E24 -> 0.04706188 | L24: =1+G24 -> 1.0128794 | M24: =PRODUCT($L$2:L24)-1 -> 0.14058409 | N24: =PRODUCT($L$2:L24)-1 -> 0.14058409 | O24: =AVERAGE($G$2:G24)*252 -> 1.4551414 | P24: =STDEV($G$2:G24)*252^0.5 -> 0.14351846
A25: 44049 | B25: 8505200.1 | D25: =B25 -> 8505200.1 | E25: =IF(MONTH(A25)=MONTH(A24),E24,D24) -> 8019590.3 | F25: =B25-C25-D24 -> 108192.83 | G25: =F25/B24 -> 0.012884689 | J25: =IF(MONTH(A25)=MONTH(A24),J24+F25,F25) -> 485609.83 | K25: =J25/E25 -> 0.060552947 | L25: =1+G25 -> 1.0128847 | M25: =PRODUCT($L$2:L25)-1 -> 0.15528017 | N25: =PRODUCT($L$2:L25)-1 -> 0.15528017 | O25: =AVERAGE($G$2:G25)*252 -> 1.5297997 | P25: =STDEV($G$2:G25)*252^0.5 -> 0.14224221
A26: 44050 | B26: 8196625.5 | D26: =B26 -> 8196625.5 | E26: =IF(MONTH(A26)=MONTH(A25),E25,D25) -> 8019590.3 | F26: =B26-C26-D25 -> -308574.63 | G26: =F26/B25 -> -0.036280702 | J26: =IF(MONTH(A26)=MONTH(A25),J25+F26,F26) -> 177035.2 | K26: =J26/E26 -> 0.022075342 | L26: =1+G26 -> 0.9637193 | M26: =PRODUCT($L$2:L26)-1 -> 0.11336579 | N26: =PRODUCT($L$2:L26)-1 -> 0.11336579 | O26: =AVERAGE($G$2:G26)*252 -> 1.1028982 | P26: =STDEV($G$2:G26)*252^0.5 -> 0.19357081
A27: 44053 | B27: 7879783.9 | D27: =B27 -> 7879783.9 | E27: =IF(MONTH(A27)=MONTH(A26),E26,D26) -> 8019590.3 | F27: =B27-C27-D26 -> -316841.56 | G27: =F27/B26 -> -0.038655122 | J27: =IF(MONTH(A27)=MONTH(A26),J26+F27,F27) -> -139806.36 | K27: =J27/E27 -> -0.017433105 | L27: =1+G27 -> 0.96134488 | M27: =PRODUCT($L$2:L27)-1 -> 0.0703285 | N27: =PRODUCT($L$2:L27)-1 -> 0.0703285 | O27: =AVERAGE($G$2:G27)*252 -> 0.68582174 | P27: =STDEV($G$2:G27)*252^0.5 -> 0.23220333
A28: 44054 | B28: 7384368.2 | D28: =B28 -> 7384368.2 | E28: =IF(MONTH(A28)=MONTH(A27),E27,D27) -> 8019590.3 | F28: =B28-C28-D27 -> -495415.76 | G28: =F28/B27 -> -0.062871744 | J28: =IF(MONTH(A28)=MONTH(A27),J27+F28,F28) -> -635222.12 | K28: =J28/E28 -> -0.079208799 | L28: =1+G28 -> 0.93712826 | M28: =PRODUCT($L$2:L28)-1 -> 0.0030350806 | N28: =PRODUCT($L$2:L28)-1 -> 0.0030350806 | O28: =AVERAGE($G$2:G28)*252 -> 0.07361799 | P28: =STDEV($G$2:G28)*252^0.5 -> 0.30331673
A29: 44055 | B29: 7585400.9 | D29: =B29 -> 7585400.9 | E29: =IF(MONTH(A29)=MONTH(A28),E28,D28) -> 8019590.3 | F29: =B29-C29-D28 -> 201032.72 | G29: =F29/B28 -> 0.027224092 | J29: =IF(MONTH(A29)=MONTH(A28),J28+F29,F29) -> -434189.4 | K29: =J29/E29 -> -0.054141095 | L29: =1+G29 -> 1.0272241 | M29: =PRODUCT($L$2:L29)-1 -> 0.0303418 | N29: =PRODUCT($L$2:L29)-1 -> 0.0303418 | O29: =AVERAGE($G$2:G29)*252 -> 0.31600561 | P29: =STDEV($G$2:G29)*252^0.5 -> 0.30841784
A30: 44056 | B30: 7631434.3 | D30: =B30 -> 7631434.3 | E30: =IF(MONTH(A30)=MONTH(A29),E29,D29) -> 8019590.3 | F30: =B30-C30-D29 -> 46033.38 | G30: =F30/B29 -> 0.0060686812 | J30: =IF(MONTH(A30)=MONTH(A29),J29+F30,F30) -> -388156.02 | K30: =J30/E30 -> -0.048400979 | L30: =1+G30 -> 1.0060687 | M30: =PRODUCT($L$2:L30)-1 -> 0.036594616 | N30: =PRODUCT($L$2:L30)-1 -> 0.036594616 | O30: =AVERAGE($G$2:G30)*252 -> 0.35784361 | P30: =STDEV($G$2:G30)*252^0.5 -> 0.30319269
A31: 44057 | B31: 7623006.3 | D31: =B31 -> 7623006.3 | E31: =IF(MONTH(A31)=MONTH(A30),E30,D30) -> 8019590.3 | F31: =B31-C31-D30 -> -8427.99 | G31: =F31/B30 -> -0.0011043782 | J31: =IF(MONTH(A31)=MONTH(A30),J30+F31,F31) -> -396584.01 | K31: =J31/E31 -> -0.049451904 | L31: =1+G31 -> 0.99889562 | M31: =PRODUCT($L$2:L31)-1 -> 0.035449823 | N31: =PRODUCT($L$2:L31)-1 -> 0.035449823 | O31: =AVERAGE($G$2:G31)*252 -> 0.33663871 | P31: =STDEV($G$2:G31)*252^0.5 -> 0.29800919
A32: 44060 | B32: 7922402.5 | D32: =B32 -> 7922402.5 | E32: =IF(MONTH(A32)=MONTH(A31),E31,D31) -> 8019590.3 | F32: =B32-C32-D31 -> 299396.17 | G32: =F32/B31 -> 0.039275341 | J32: =IF(MONTH(A32)=MONTH(A31),J31+F32,F32) -> -97187.84 | K32: =J32/E32 -> -0.012118804 | L32: =1+G32 -> 1.0392753 | M32: =PRODUCT($L$2:L32)-1 -> 0.076117468 | N32: =PRODUCT($L$2:L32)-1 -> 0.076117468 | O32: =AVERAGE($G$2:G32)*252 -> 0.64504991 | P32: =STDEV($G$2:G32)*252^0.5 -> 0.31233015
A33: 44061 | B33: 8026372.1 | D33: =B33 -> 8026372.1 | E33: =IF(MONTH(A33)=MONTH(A32),E32,D32) -> 8019590.3 | F33: =B33-C33-D32 -> 103969.61 | G33: =F33/B32 -> 0.013123495 | J33: =IF(MONTH(A33)=MONTH(A32),J32+F33,F33) -> 6781.77 | K33: =J33/E33 -> 0.00084565043 | L33: =1+G33 -> 1.0131235 | M33: =PRODUCT($L$2:L33)-1 -> 0.090239891 | N33: =PRODUCT($L$2:L33)-1 -> 0.090239891 | O33: =AVERAGE($G$2:G33)*252 -> 0.72823962 | P33: =STDEV($G$2:G33)*252^0.5 -> 0.30867805
... A42: 44074 | B42: 8142193.1 | D42: =B42 -> 8142193.1 | E42: =IF(MONTH(A42)=MONTH(A41),E41,D41) -> 8019590.3 | F42: =B42-C42-D41 -> 290346.71 | G42: =F42/B41 -> 0.036978144 | J42: =IF(MONTH(A42)=MONTH(A41),J41+F42,F42) -> 122602.8 | K42: =J42/E42 -> 0.015287913 | L42: =1+G42 -> 1.0369781 | M42: =PRODUCT($L$2:L42)-1 -> 0.10597212 | N42: =PRODUCT($L$2:L42)-1 -> 0.10597212 | O42: =AVERAGE($G$2:G42)*252 -> 0.66509521 | P42: =STDEV($G$2:G42)*252^0.5 -> 0.30262598
A43: 44075 | B43: 8932854.6 | C43: 340000 | D43: =B43 -> 8932854.6 | E43: =IF(MONTH(A43)=MONTH(A42),E42,D42) -> 8142193.1 | F43: =790661.47-C43 -> 450661.47 | G43: 0.0531 | J43: =IF(MONTH(A43)=MONTH(A42),J42+F43,F43) -> 450661.47 | K43: =G43 -> 0.0531 | L43: =1+G43 -> 1.0531 | M43: =PRODUCT($L$2:L43)-1 -> 0.16469924 | N43: =PRODUCT($L$2:L43)-1 -> 0.16469924 | O43: =AVERAGE($G$2:G43)*252 -> 0.96785961 | P43: =STDEV($G$2:G43)*252^0.5 -> 0.32346017
A44: 44076 | B44: 8942808.3 | D44: =B44 -> 8942808.3 | E44: =IF(MONTH(A44)=MONTH(A43),E43,D43) -> 8142193.1 | F44: =B44-C44-D43 -> 9953.78 | G44: =F44/B43 -> 0.0011142888 | J44: =IF(MONTH(A44)=MONTH(A43),J43+F44,F44) -> 460615.25 | K44: 0.0543 | L44: =1+G44 -> 1.0011143 | M44: =PRODUCT($L$2:L44)-1 -> 0.16599705 | N44: =PRODUCT($L$2:L44)-1 -> 0.16599705 | O44: =AVERAGE($G$2:G44)*252 -> 0.9518815 | P44: =STDEV($G$2:G44)*252^0.5 -> 0.3196544
A45: 44077 | B45: 18349287 | C45: 10000000 | D45: =B45 -> 18349287 | E45: =IF(MONTH(A45)=MONTH(A44),E44,D44) -> 8142193.1 | F45: =B45-C45-D44 -> -593521.57 | G45: -0.0313 | J45: =IF(MONTH(A45)=MONTH(A44),J44+F45,F45) -> -132906.32 | K45: 0.0213 | L45: =1+G45 -> 0.9687 | M45: =PRODUCT($L$2:L45)-1 -> 0.12950134 | N45: =PRODUCT($L$2:L45)-1 -> 0.12950134 | O45: =AVERAGE($G$2:G45)*252 -> 0.75098419 | P45: =STDEV($G$2:G45)*252^0.5 -> 0.3268786
A46: 44078 | B46: 17844069 | D46: =B46 -> 17844069 | E46: =IF(MONTH(A46)=MONTH(A45),E45,D45) -> 8142193.1 | F46: =B46-C46-D45 -> -505217.29 | G46: =F46/B45 -> -0.027533348 | J46: =IF(MONTH(A46)=MONTH(A45),J45+F46,F46) -> -638123.61 | K46: -0.0068 | L46: =1+G46 -> 0.97246665 | M46: =PRODUCT($L$2:L46)-1 -> 0.098402388 | N46: =PRODUCT($L$2:L46)-1 -> 0.098402388 | O46: =AVERAGE($G$2:G46)*252 -> 0.58010891 | P46: =STDEV($G$2:G46)*252^0.5 -> 0.33111208
A47: 44081 | B47: 17832817 | D47: =B47 -> 17832817 | E47: =IF(MONTH(A47)=MONTH(A46),E46,D46) -> 8142193.1 | F47: =B47-C47-D46 -> -11252.47 | G47: =F47/B46 -> -0.00063059999 | J47: =IF(MONTH(A47)=MONTH(A46),J46+F47,F47) -> -649376.08 | K47: -0.0075 | L47: =1+G47 -> 0.9993694 | M47: =PRODUCT($L$2:L47)-1 -> 0.097709735 | N47: =PRODUCT($L$2:L47)-1 -> 0.097709735 | O47: =AVERAGE($G$2:G47)*252 -> 0.56404326 | P47: =STDEV($G$2:G47)*252^0.5 -> 0.32748433
A48: 44082 | B48: 17315845 | D48: =B48 -> 17315845 | E48: =IF(MONTH(A48)=MONTH(A47),E47,D47) -> 8142193.1 | F48: =B48-C48-D47 -> -516971.74 | G48: =F48/B47 -> -0.028989909 | J48: =IF(MONTH(A48)=MONTH(A47),J47+F48,F48) -> -1166347.8 | K48: -0.0362 | L48: =1+G48 -> 0.97101009 | M48: =PRODUCT($L$2:L48)-1 -> 0.06588723 | N48: =PRODUCT($L$2:L48)-1 -> 0.06588723 | O48: =AVERAGE($G$2:G48)*252 -> 0.39660708 | P48: =STDEV($G$2:G48)*252^0.5 -> 0.33187841
...

Sheet Mark to Market
A1: Mark to Market Breakdown
A2: Symbol | B2: AssetClass | C2: Currency | D2: Current Quantity | E2: Current Price | F2: FCY_marketvalue | G2: Conversion Rate | H2: Final_marketvalue | I2: Weightage
A3: SGOV | B3: Bonds | C3: USD | D3: 207975 | E3: 100.51 | F3: 20903567 | G3: 1 | H3: 20903567 | I3: 100

Sheet Daily P&L breakdown
A1: Date | B1: ETFs | C1: Stocks_int | D1: Stocks | E1: Bonds | F1: Commodities | G1: Future | H1: Option | I1: Crypto | J1: Others | K1: Others2 | L1: Total
A2: ='Historical NAV'!A994 -> 45413 | B2: -1970094.7 | C2: 0 | D2: -313917.4 | E2: -5998.97 | F2: 122642.36 | H2: 0 | L2: =SUM(B2:K2) -> -2167368.7
A3: ='Historical NAV'!A995 -> 45414 | B3: 2436118.4 | C3: 23250.47 | D3: 259278.4 | E3: 51716.52 | F3: 10509.84 | H3: 0 | L3: =SUM(B3:K3) -> 2780873.6
A4: ='Historical NAV'!A996 -> 45415 | B4: 2771769.6 | C4: 154804.98 | D4: 277584.8 | E4: 50177.07 | F4: 13860.98 | H4: 0 | L4: =SUM(B4:K4) -> 3268197.5
A5: ='Historical NAV'!A997 -> 45418 | B5: 2346005.5 | C5: -119425.76 | D5: 312983.4 | E5: 15660.96 | F5: 137325.26 | H5: 0 | L5: =SUM(B5:K5) -> 2692549.4
A6: ='Historical NAV'!A998 -> 45419 | B6: -507593.41 | C6: 23032.62 | D6: -148132.4 | E6: 34299.14 | F6: -25473.91 | H6: 0 | L6: =SUM(B6:K6) -> -623867.96
A7: ='Historical NAV'!A999 -> 45420 | B7: 152959.43 | C7: -76052.85 | D7: -13262.8 | E7: -19711.85 | F7: -73297.26 | H7: 0 | L7: =SUM(B7:K7) -> -29365.33
A8: ='Historical NAV'!A1000 -> 45421 | B8: 139090.48 | C8: 202257.72 | D8: -155511 | E8: 9588.08 | F8: 204666.24 | H8: 0 | L8: =SUM(B8:K8) -> 400091.52
A9: ='Historical NAV'!A1001 -> 45422 | B9: 653912.02 | C9: 562316.1 | D9: 105635.4 | E9: -24363.21 | F9: 58651.75 | H9: 0 | L9: =SUM(B9:K9) -> 1356152.1
A10: ='Historical NAV'!A1002 -> 45425 | B10: 91627.43 | C10: -153587.82 | D10: 48661.4 | E10: 4116.74 | F10: -155030.89 | H10: 0 | L10: =SUM(B10:K10) -> -164213.14
A11: ='Historical NAV'!A1003 -> 45426 | B11: 1227745 | C11: -179070.84 | D11: 89383.8 | E11: 20723.99 | F11: 101843.55 | H11: 0 | L11: =SUM(B11:K11) -> 1260625.5
A12: ='Historical NAV'!A1004 -> 45427 | B12: 2264910.6 | C12: -2106.92 | D12: 305791.6 | E12: 64874.77 | F12: 146691.54 | H12: 0 | L12: =SUM(B12:K12) -> 2780161.6
A13: ='Historical NAV'!A1005 -> 45428 | B13: -599659.93 | C13: 72779.26 | D13: -25311.4 | E13: -13198.09 | F13: -45519.6 | H13: 0 | L13: =SUM(B13:K13) -> -610909.76
... A32: ='Historical NAV'!A1024 -> 45455 | B32: 1455137.8 | C32: -15513.11 | D32: 478169.94 | E32: 45660.71 | F32: 63545.75 | H32: 21422.55 | L32: =SUM(B32:K32) -> 2048423.6
A33: ='Historical NAV'!A1025 -> 45456 | B33: -72270.02 | C33: -139433.15 | D33: 455390.56 | E33: 31311.89 | F33: -191213.19 | G33: -300 | H33: 39563.89 | L33: =SUM(B33:K33) -> 123049.98
A34: ='Historical NAV'!A1026 -> 45457 | B34: -222728.21 | C34: -102600.35 | D34: 231071.47 | E34: -4070.66 | F34: 109071.7 | G34: 162.8 | H34: 3590.57 | L34: =SUM(B34:K34) -> 14497.32
A35: ='Historical NAV'!A1027 -> 45460 | B35: 1143293.3 | C35: -150055.4 | D35: -57615 | E35: -23422.15 | F35: -116714.4 | G35: 0 | H35: 28076.3 | L35: =SUM(B35:K35) -> 823562.61
A36: ='Historical NAV'!A1028 -> 45461 | B36: 542224.08 | C36: -22841.94 | D36: 520943.88 | E36: 31896.94 | F36: 109318.26 | G36: -586.5 | H36: 13783.84 | L36: =SUM(B36:K36) -> 1194738.6
A37: ='Historical NAV'!A1029 -> 45462 | B37: 0 | C37: 889806.69 | D37: 0 | E37: 0 | F37: 0 | G37: 0 | H37: -2034.45 | L37: =SUM(B37:K37) -> 887772.24
A38: ='Historical NAV'!A1030 -> 45463 | B38: -686347.1 | C38: 300120.46 | D38: -762729.19 | E38: -19123.09 | F38: 194246.51 | G38: 2971.88 | H38: -6859.5 | L38: =SUM(B38:K38) -> -977720.03
A39: ='Historical NAV'!A1031 -> 45464 | B39: -424152.6 | C39: -521624.46 | D39: -499358.56 | E39: 5989.15 | F39: -255987.4 | G39: 0 | H39: 31958.5 | L39: =SUM(B39:K39) -> -1663175.4
A40: ='Historical NAV'!A1032 -> 45467 | B40: -814310 | C40: 50237.97 | D40: -1243576.4 | E40: 3747.87 | F40: 78430.83 | G40: 0 | H40: 8300.73 | L40: =SUM(B40:K40) -> -1917169
A41: ='Historical NAV'!A1033 -> 45468 | B41: 780248.49 | C41: 65843.85 | D41: 1340503.9 | E41: 50.64 | F41: -172901.05 | G41: 0 | H41: -71164.1 | L41: =SUM(B41:K41) -> 1942581.7
A42: ='Historical NAV'!A1034 -> 45469 | B42: -134543.06 | C42: -126431.6 | D42: 33773.99 | E42: -34214.78 | F42: -119773.58 | G42: 0 | H42: 14710.28 | L42: =SUM(B42:K42) -> -366478.75
A43: ='Historical NAV'!A1035 -> 45470 | B43: 136300.68 | C43: -708946.39 | D43: -597843 | E43: 13661.86 | F43: 132769.33 | G43: 0 | H43: 186852.56 | L43: =SUM(B43:K43) -> -837204.96
A44: ='Historical NAV'!A1036 -> 45471 | B44: 247789.23 | C44: 466048.59 | D44: 23974.8 | E44: -33182.84 | F44: 49235.3 | G44: -11275 | H44: 65841.58 | L44: =SUM(B44:K44) -> 808431.66
... A56: ='Historical NAV'!A1048 -> 45489 | B56: 1004163.4 | C56: -250796.76 | D56: -195364.75 | E56: 84453.55 | F56: 302809.42 | G56: 1035 | H56: 5208.3 | L56: =SUM(B56:K56) -> 951508.17
A57: ='Historical NAV'!A1049 -> 45490 | B57: =-3359461.34-66757.2 -> -3426218.5 | C57: -613418.23 | D57: -2253430.8 | E57: -22051.99 | F57: -282468.43 | G57: 0 | H57: -22412.47 | L57: =SUM(B57:K57) -> -6620000.5
A58: ='Historical NAV'!A1050 -> 45491 | B58: -972898.82 | C58: 99684.86 | D58: 114083.79 | E58: -64523.55 | F58: -155600.85 | G58: 0 | H58: 107578.22 | L58: =SUM(B58:K58) -> -871676.35
A59: ='Historical NAV'!A1051 -> 45492 | B59: -1228709 | C59: -476140.2 | D59: -728557.26 | E59: -38397.45 | F59: -436590.09 | G59: -312.35 | H59: 23373.75 | L59: =SUM(B59:K59) -> -2885332.6
A60: ='Historical NAV'!A1052 -> 45495 | B60: 1378132.4 | C60: 144299.29 | D60: 945666.4 | E60: 20972.52 | F60: -12091.11 | G60: 637.5 | H60: 44207.43 | L60: =SUM(B60:K60) -> 2521824.4
A61: ='Historical NAV'!A1053 -> 45496 | B61: -524853.7 | C61: -80446.59 | D61: -131135.23 | E61: -11455.05 | F61: -36991.83 | G61: 2156.25 | H61: 3964.32 | L61: =SUM(B61:K61) -> -778761.83
A62: ='Historical NAV'!A1054 -> 45497 | B62: -2418257.9 | C62: -12538.97 | D62: -1663639.3 | E62: -102396.6 | F62: -154432.84 | G62: 441086.85 | H62: 128974.68 | L62: =SUM(B62:K62) -> -3781204.1
A63: ='Historical NAV'!A1055 -> 45498 | B63: -139113.7 | C63: -333649.61 | D63: -233070.94 | E63: 35824.52 | F63: -338913.56 | G63: 116466.67 | H63: 87157.4 | L63: =SUM(B63:K63) -> -805299.22
A64: ='Historical NAV'!A1056 -> 45499 | B64: 1354522.6 | C64: 29227.42 | D64: 201949.39 | E64: 72407.7 | F64: 307604.64 | G64: 64760.25 | H64: 38479.95 | L64: =SUM(B64:K64) -> 2068952
A65: ='Historical NAV'!A1057 -> 45502 | B65: -302201.08 | C65: 297398.18 | D65: =-281644.21-90000 -> -371644.21 | E65: 19921.18 | F65: -64154.74 | G65: =-90468.12+90000 -> -468.12 | H65: 66591.13 | L65: =SUM(B65:K65) -> -354557.66
A66: ='Historical NAV'!A1058 -> 45503 | B66: -530420.34 | C66: -277334.39 | D66: -1354623.5 | E66: 21589.52 | F66: 163519.92 | G66: -175465 | H66: 5932.33 | L66: =SUM(B66:K66) -> -2146801.5
A67: ='Historical NAV'!A1059 -> 45504 | B67: 2049105.6 | C67: 237889.3 | D67: 2435149.3 | E67: 102279.83 | F67: 519853.99 | G67: 337501.95 | H67: 171208.22 | L67: =SUM(B67:K67) -> 5852988.2
A68: ='Historical NAV'!A1060 -> 45505 | B68: -2866463.5 | C68: 29753.27 | D68: -1512431 | E68: -38964.42 | F68: -428467.99 | G68: 180673.21 | H68: -77397.23 | L68: =SUM(B68:K68) -> -4713297.7
A69: ='Historical NAV'!A1061 -> 45506 | B69: -2717185.6 | C69: -334600.58 | D69: -812418.47 | E69: 65754.13 | F69: -268584.16 | G69: 941518.65 | H69: -54915.51 | L69: =SUM(B69:K69) -> -3180431.5
...

Sheet Email
B2: Performance Comparisons | N2: Global Macro Discretionary Fund Breakdowns | S2: Monthly NAV Breakdowns
B3: Us v.s Benchmarks | C3: Description | D3: Week 1 | E3: Week 2 | F3: Week 3 | G3: Week 4 | H3: Week 5 | I3: Daily | J3: MTD | K3: MTD | L3: YTD | O3: Inhouse | P3: Quantedge | Q3: Total | S3: Starting Value | T3: =ROUND(VLOOKUP("Starting Value", 'Email input'!C:D, 2, FALSE),2) -> 66302018
B4: Inhouse | C4: Straits Multi-Asset Macro Strategy | D4: =IF(D18=0, "", D18) -> 0.0017 | E4: =IF(E18=0, "", E18) -> 0.0030108225 | F4: =IF(F18=0, "", F18) -> -0.6851328 | G4: =IF(G18=0, "", G18) | H4: =IF(H18=0, "", H18) | I4: =IF(I18=0, "", I18) -> -0.6851328 | J4: =IF(J18=0, "", J18) -> -0.68349276 | K4: =J4 -> -0.68349276 | L4: =IF(L18=0, "", L18) -> -0.66335391 | N4: Starting Value | O4: =T3 -> 66302018 | P4: =P16 -> 2307179.6 | Q4: =SUM(O4:P4) -> 68609198 | S4: Deposits & Withdrawals | T4: 0 | V4: =ROUND(VLOOKUP("Deposits & Withdrawals", 'Email input'!C:D, 2, FALSE),2) -> #N/A
B5: Quantedge | C5: Singapore-based Global Macro Fund | D5: =D19 -> 0 | E5: =IF(E19=0, "", E19) -> 0.01 | F5: =IF(F19=0, "", F19) | G5: =IF(G19=0, "", G19) | H5: =IF(H19=0, "", H19) | I5: NA | J5: =SUM(D5:H5) -> 0.01 | K5: =J5 -> 0.01 | L5: =L19+J5 -> 0.083 | N5: Deposits & Withdrawals | O5: =T4 -> 0 | Q5: =SUM(O5:P5) -> 0 | S5: Commodities | T5: 0 | U5: =VLOOKUP("Commodities", 'Email input'!F:G, 2, FALSE)/100 -> #N/A
B6: SPX Index | C6: S&P 500 Index | D6: {=IFERROR(_xll.BDP($B6,"INTERVAL_PERCENT_CHANGE", "END_DATE_OVERRIDE="&TEXT(D$17,"yyyymmdd"), "START_DATE_OVERRIDE="&TEXT(D$16,"yyyymmdd"))/100, "")} -> 0.28157398 | E6: {=IFERROR(_xll.BDP($B6,"INTERVAL_PERCENT_CHANGE", "END_DATE_OVERRIDE="&TEXT(E$17,"yyyymmdd"), "START_DATE_OVERRIDE="&TEXT(E$16,"yyyymmdd"))/100, "")} -> 0.28816179 | F6: {=IFERROR(_xll.BDP($B6,"INTERVAL_PERCENT_CHANGE", "END_DATE_OVERRIDE="&TEXT(F$17,"yyyymmdd"), "START_DATE_OVERRIDE="&TEXT(F$16,"yyyymmdd"))/100, "")} -> 0.30567529 | G6: {=IFERROR(_xll.BDP($B6,"INTERVAL_PERCENT_CHANGE", "END_DATE_OVERRIDE="&TEXT(G$17,"yyyymmdd"), "START_DATE_OVERRIDE="&TEXT(G$16,"yyyymmdd"))/100, "")} -> 0.43160336 | H6: {=IFERROR(_xll.BDP($B6,"INTERVAL_PERCENT_CHANGE", "END_DATE_OVERRIDE="&TEXT(H$17,"yyyymmdd"), "START_DATE_OVERRIDE="&TEXT(H$16,"yyyymmdd"))/100, "")} -> 0.38325423 | I6: =_xll.BDP(B6,"CHG_PCT_1D")/100 -> 0.02913117 | J6: =_xll.BDP($B6,"CURRENT_TRR_MTD")/100 -> 0 | K6: =_xll.BDP(B6,"CHG_PCT_1M")/100 -> -0.05093269 | L6: {=_xll.BDP($B6,"CHG_PCT_YTD")/100} -> -0.04630487 | N6: Allocation | O6: =SUM(O4:O5)/SUM(O4:P5) -> 0.96637215 | P6: =SUM(P4:P5)/SUM(O4:P5) -> 0.033627847 | Q6: =SUM(O6:P6) -> 1 | S6: Equities | T6: =($T$3+T$4)*U6 -> 25562.79 | U6: =VLOOKUP("new_equity", 'Email input'!F:G, 2, FALSE)/100 -> 0.00038555071
B7: NDX Index | C7: Nasdaq-100 Index | D7: {=IFERROR(_xll.BDP($B7,"INTERVAL_PERCENT_CHANGE", "END_DATE_OVERRIDE="&TEXT(D$17,"yyyymmdd"), "START_DATE_OVERRIDE="&TEXT(D$16,"yyyymmdd"))/100, "")} -> 0.38788183 | E7: {=IFERROR(_xll.BDP($B7,"INTERVAL_PERCENT_CHANGE", "END_DATE_OVERRIDE="&TEXT(E$17,"yyyymmdd"), "START_DATE_OVERRIDE="&TEXT(E$16,"yyyymmdd"))/100, "")} -> 0.4061962 | F7: {=IFERROR(_xll.BDP($B7,"INTERVAL_PERCENT_CHANGE", "END_DATE_OVERRIDE="&TEXT(F$17,"yyyymmdd"), "START_DATE_OVERRIDE="&TEXT(F$16,"yyyymmdd"))/100, "")} -> 0.42138604 | G7: {=IFERROR(_xll.BDP($B7,"INTERVAL_PERCENT_CHANGE", "END_DATE_OVERRIDE="&TEXT(G$17,"yyyymmdd"), "START_DATE_OVERRIDE="&TEXT(G$16,"yyyymmdd"))/100, "")} -> 0.59640414 | H7: {=IFERROR(_xll.BDP($B7,"INTERVAL_PERCENT_CHANGE", "END_DATE_OVERRIDE="&TEXT(H$17,"yyyymmdd"), "START_DATE_OVERRIDE="&TEXT(H$16,"yyyymmdd"))/100, "")} -> 0.50684549 | I7: {=_xll.BDP(B7,"CHG_PCT_1D")/100} -> 0.03427861 | J7: {=_xll.BDP($B7,"CURRENT_TRR_MTD")/100} -> 0 | K7: =_xll.BDP(B7,"CHG_PCT_1M")/100 -> -0.0488721 | L7: {=_xll.BDP($B7,"CHG_PCT_YTD")/100} -> -0.05978888 | N7: Daily P&L | O7: =OFFSET('Historical NAV'!F1,COUNT('Historical NAV'!A:A),,,) -> -45662297 | P7: NA | Q7: =SUM(O7:P7) -> -45662297 | S7: Fixed Income | T7: =($T$3+T$4)*U7 -> 109564.51 | U7: =VLOOKUP("Fixed Income", 'Email input'!F:G, 2, FALSE)/100 -> 0.0016525064
B8: MXWO Index | C8: MSCI World Index | D8: {=IFERROR(_xll.BDP($B8,"INTERVAL_PERCENT_CHANGE", "END_DATE_OVERRIDE="&TEXT(D$17,"yyyymmdd"), "START_DATE_OVERRIDE="&TEXT(D$16,"yyyymmdd"))/100, "")} -> 0.19076125 | E8: {=IFERROR(_xll.BDP($B8,"INTERVAL_PERCENT_CHANGE", "END_DATE_OVERRIDE="&TEXT(E$17,"yyyymmdd"), "START_DATE_OVERRIDE="&TEXT(E$16,"yyyymmdd"))/100, "")} -> 0.19476276 | F8: {=IFERROR(_xll.BDP($B8,"INTERVAL_PERCENT_CHANGE", "END_DATE_OVERRIDE="&TEXT(F$17,"yyyymmdd"), "START_DATE_OVERRIDE="&TEXT(F$16,"yyyymmdd"))/100, "")} -> 0.20330426 | G8: {=IFERROR(_xll.BDP($B8,"INTERVAL_PERCENT_CHANGE", "END_DATE_OVERRIDE="&TEXT(G$17,"yyyymmdd"), "START_DATE_OVERRIDE="&TEXT(G$16,"yyyymmdd"))/100, "")} -> 0.31208216 | H8: {=IFERROR(_xll.BDP($B8,"INTERVAL_PERCENT_CHANGE", "END_DATE_OVERRIDE="&TEXT(H$17,"yyyymmdd"), "START_DATE_OVERRIDE="&TEXT(H$16,"yyyymmdd"))/100, "")} -> 0.29417658 | I8: {=_xll.BDP(B8,"CHG_PCT_1D")/100} -> 0.02270466 | J8: {=_xll.BDP($B8,"CURRENT_TRR_MTD")/100} -> 4.311423e-05 | K8: =_xll.BDP(B8,"CHG_PCT_1M")/100 -> -0.06550225 | L8: {=_xll.BDP($B8,"CHG_PCT_YTD")/100} -> -0.03883862 | N8: MTD P&L before fee | O8: =OFFSET('Historical NAV'!J1,COUNT('Historical NAV'!A:A),,,) -> -45662297 | P8: =SUM(P4:P5)*P9 -> 23071.796 | Q8: =SUM(O8:P8) -> -45639225 | S8: Cash | T8: =($T$3+T$4)*U8 -> 194892.03 | U8: =VLOOKUP("Cash", 'Email input'!F:G, 2, FALSE)/100 -> 0.0029394585
B9: SBWGU Index | C9: FTSE World Government Bond Index | D9: {=IFERROR(_xll.BDP($B9,"INTERVAL_PERCENT_CHANGE", "END_DATE_OVERRIDE="&TEXT(D$17,"yyyymmdd"), "START_DATE_OVERRIDE="&TEXT(D$16,"yyyymmdd"))/100, "")} -> -0.15068936 | E9: {=IFERROR(_xll.BDP($B9,"INTERVAL_PERCENT_CHANGE", "END_DATE_OVERRIDE="&TEXT(E$17,"yyyymmdd"), "START_DATE_OVERRIDE="&TEXT(E$16,"yyyymmdd"))/100, "")} -> -0.14623118 | F9: {=IFERROR(_xll.BDP($B9,"INTERVAL_PERCENT_CHANGE", "END_DATE_OVERRIDE="&TEXT(F$17,"yyyymmdd"), "START_DATE_OVERRIDE="&TEXT(F$16,"yyyymmdd"))/100, "")} -> -0.14696936 | G9: {=IFERROR(_xll.BDP($B9,"INTERVAL_PERCENT_CHANGE", "END_DATE_OVERRIDE="&TEXT(G$17,"yyyymmdd"), "START_DATE_OVERRIDE="&TEXT(G$16,"yyyymmdd"))/100, "")} -> -0.1349148 | H9: {=IFERROR(_xll.BDP($B9,"INTERVAL_PERCENT_CHANGE", "END_DATE_OVERRIDE="&TEXT(H$17,"yyyymmdd"), "START_DATE_OVERRIDE="&TEXT(H$16,"yyyymmdd"))/100, "")} -> -0.1334153 | I9: {=_xll.BDP(B9,"CHG_PCT_1D")/100} -> 0.003071177 | J9: {=_xll.BDP($B9,"CURRENT_TRR_MTD")/100} -> 0 | K9: =_xll.BDP(B9,"CHG_PCT_1M")/100 -> -0.03182128 | L9: {=_xll.BDP($B9,"CHG_PCT_YTD")/100} -> -0.01050591 | N9: MTD P&L before fee (%) | O9: =OFFSET('Historical NAV'!K1,COUNT('Historical NAV'!A:A),,,) -> -0.68349276 | P9: =J5 -> 0.01 | S9: Total Trading P&L | T9: =SUM(T5:T8) -> 330019.33 | V9: =T9/(T3+T4) -> 0.0049775156
B10: BCOM Index | C10: Bloomberg Commodity Index | D10: {=IFERROR(_xll.BDP($B10,"INTERVAL_PERCENT_CHANGE", "END_DATE_OVERRIDE="&TEXT(D$17,"yyyymmdd"), "START_DATE_OVERRIDE="&TEXT(D$16,"yyyymmdd"))/100, "")} -> -0.10435881 | E10: {=IFERROR(_xll.BDP($B10,"INTERVAL_PERCENT_CHANGE", "END_DATE_OVERRIDE="&TEXT(E$17,"yyyymmdd"), "START_DATE_OVERRIDE="&TEXT(E$16,"yyyymmdd"))/100, "")} -> -0.093448329 | F10: {=IFERROR(_xll.BDP($B10,"INTERVAL_PERCENT_CHANGE", "END_DATE_OVERRIDE="&TEXT(F$17,"yyyymmdd"), "START_DATE_OVERRIDE="&TEXT(F$16,"yyyymmdd"))/100, "")} -> -0.08010459 | G10: {=IFERROR(_xll.BDP($B10,"INTERVAL_PERCENT_CHANGE", "END_DATE_OVERRIDE="&TEXT(G$17,"yyyymmdd"), "START_DATE_OVERRIDE="&TEXT(G$16,"yyyymmdd"))/100, "")} -> -0.095390816 | H10: {=IFERROR(_xll.BDP($B10,"INTERVAL_PERCENT_CHANGE", "END_DATE_OVERRIDE="&TEXT(H$17,"yyyymmdd"), "START_DATE_OVERRIDE="&TEXT(H$16,"yyyymmdd"))/100, "")} -> -0.16477792 | I10: =_xll.BDP(B10,"CHG_PCT_1D")/100 -> -0.006231608 | J10: {=_xll.BDP($B10,"CURRENT_TRR_MTD")/100} -> -0.006231637 | K10: =_xll.BDP(B10,"CHG_PCT_1M")/100 -> 0.1045347 | L10: {=_xll.BDP($B10,"CHG_PCT_YTD")/100} -> 0.2253004 | N10: Ending Value | O10: =O4+O5+O8 -> 20639722 | P10: =P4+P5+P8 -> 2330251.4 | Q10: =SUM(O10:P10) -> 22969973 | S10: Interest and Dividend related | T10: =SUM('Email input'!D5:D6) -> 163158.58
S11: Hardcode | T11: -170897.33
S12: Other Trading Cost | T12: =SUM('Email input'!D7:D9) -> 23066.663
S13: Ending Value | T13: =T3+T4+T9+T10+T12+T11 -> 66647366
B16: start date | D16: 44594 | E16: =D16+7 -> 44601 | F16: =E16+7 -> 44608 | G16: =F16+7 -> 44615 | H16: =G16+7 -> 44622 | N16: Quantedge NAV | P16: 2307179.6 | S16: nav | T16: =OFFSET('Historical NAV'!B1,COUNT('Historical NAV'!A:A),,,) -> 20985069
B17: end date | D17: 45657 | E17: =D17+7 -> 45664 | F17: =E17+7 -> 45671 | G17: =F17+7 -> 45678 | H17: =G17+7 -> 45685 | P17: 45688 | T17: =T13 -> 66647366
B18: buy and hold | D18: 0.0017 | E18: 0.0030108225 | F18: =Dashboard!$B$4 -> -0.6851328 | I18: =Dashboard!B9 -> -0.6851328 | J18: =Dashboard!B5 -> -0.68349276 | L18: =Dashboard!B6 -> -0.66335391 | T18: =T16-T17 -> -45662297
B19: qe | D19: 0 | E19: 0.01 | J19: =SUM(D19:H19) -> 0.01 | L19: 0.073 | M19: =P17 -> 45688

Sheet Email input
A1: Change in NAV | B1: Header | C1: Field Name | D1: Field Value | F1: Performance by Asset Class | G1: Performance by Asset Class
A2: Change in NAV | B2: Data | C2: Starting Value | D2: 66302018 | F2: Header | G2: Data
A3: Change in NAV | B3: Data | C3: Mark-to-Market | D3: 161244 | F3: Date | G3: Total
A4: Change in NAV | B4: Data | C4: Dividends | D4: 1452.82 | F4: Fixed Income | G4: 0.16525064
A5: Change in NAV | B5: Data | C5: Withholding Tax | D5: 164167.45 | F5: Cash | G5: 0.29394585
A6: Change in NAV | B6: Data | C6: Change in Dividend Accruals | D6: -1008.87
A7: Change in NAV | B7: Data | C7: Interest | D7: -472182.15
A8: Change in NAV | B8: Data | C8: Change in Interest Accruals | D8: 495445.25
A9: Change in NAV | B9: Data | C9: Other Fees | D9: -196.44 | F9: new_equity | G9: 0.038555071
A10: Change in NAV | B10: Data | C10: Commissions | D10: -3444.821
A11: Change in NAV | B11: Data | C11: Other FX Translations | D11: -130.00165
A12: Change in NAV | B12: Data | C12: Ending Value | D12: 66647366

Sheet QuantEdge
A1: Dates | B1: MTD
A2: 44013 | B2: -0.0146
A3: 44014 | B3: 0.0014
A4: 44015 | B4: 0.0042
A5: 44018 | B5: 0.018
A6: 44019 | B6: 0.0235
A7: 44021 | B7: 0.0407
A8: 44022 | B8: 0.0392
A9: 44025 | B9: 0.0466
A10: 44026 | B10: 0.0514
A11: 44027 | B11: 0.06
A12: 44028 | B12: 0.0572
A13: 44029 | B13: 0.0521
... A647: 45632 | B647: 0.03
A648: =A647+7 -> 45639 | B648: 0.03
A649: =A648+7 -> 45646 | B649: -0.03
A650: =A649+7+4 -> 45657 | B650: -0.026
A651: 45674 | B651: 0.01

Sheet Categorized P&L
B1: Previos Month | C1: 202406
B2: YTD Return (before fees) - TOTAL | C2: 0.033335414
B3: YTD Return (before fees) - IN-HOUSE BUY AND HOLD | C3: 0.046278035
B4: YTD Return (before fees) - QE | C4: 0.168272
C6: Total (USD) | D6: In-House Buy & Hold (USD) | E6: QuantEdge (USD) | F6: Global Sigma(USD)
B7: Month Start NAV | C7: =SUM(D7:F7)+D8 -> 68579961 | D7: =OFFSET('Historical NAV'!E1, COUNT('Historical NAV'!B:B),,,) -> 66647366 | E7: 1932595.1 | F7: 0
B8: Subscription
B9: Percentage | C9: =SUM(D9:F9) -> 1 | D9: =(D7+D8)/(D7+D8+E7) -> 0.97181983 | E9: =E7/(D7+D8+E7) -> 0.028180172 | F9: 0
B10: Portfolio NAV | C10: =SUM(D10:F10) -> #REF! | D10: =OFFSET('Historical NAV'!B1, COUNT('Historical NAV'!B:B),,,) -> 20985069 | E10: =E7+E11 -> #REF! | F10: =F7+F11 -> 0
B11: MTD P&L | C11: =SUM(D11:F11) -> #REF! | D11: =OFFSET('Historical NAV'!J1, COUNT('Historical NAV'!B:B),,,) -> -45662297 | E11: =E12*E7 -> #REF! | F11: =F12*F7 -> 0
B12: MTD Return (before fees) | C12: =D12*D9+E12*E9 -> #REF! | D12: =OFFSET('Historical NAV'!K1, COUNT('Historical NAV'!B:B),,,) -> -0.68349276 | E12: =OFFSET(#REF!, COUNT(#REF!),,,) -> #REF! | F12: 0
B13: YTD Return (before fees) | C13: =(1+C2)*(1+C12)-1 -> #REF! | D13: =(1+C3)*(1+D12)-1 -> -0.66884542 | E13: =(1+C4)*(1+E12)-1 -> #REF!
B14: Daily Change | D14: =OFFSET('Historical NAV'!G1, COUNT('Historical NAV'!B:B),,,) -> -0.6851328 | E14: NA

Sheet IB_Margin
A1: Date | B1: NAV(Net Liquidity) | C1: Maintenance | D1: Excess Liquidity | E1: Alert | F1: IB Alert 10% | G1: IB Alert 15% | H1: Excess Liquidity/NAV
A2: 45170 | B2: 37374972 | C2: 10706569 | D2: =B2-C2 -> 26668403 | E2: =B2*0.25 -> 9343742.9 | F2: =B2*0.1 -> 3737497.2 | G2: =B2*0.15 -> 5606245.7 | H2: =D2/B2 -> 0.7135364
A3: 45171 | B3: 37374972 | C3: 10706569 | D3: =B3-C3 -> 26668403 | E3: =B3*0.25 -> 9343742.9 | F3: =B3*0.1 -> 3737497.2 | G3: =B3*0.15 -> 5606245.7 | H3: =D3/B3 -> 0.7135364
A4: 45173 | B4: 37375362 | C4: 10705819 | D4: =B4-C4 -> 26669543 | E4: =B4*0.25 -> 9343840.6 | F4: =B4*0.1 -> 3737536.2 | G4: =B4*0.15 -> 5606304.4 | H4: =D4/B4 -> 0.71355945
A5: 45174 | B5: 37340919 | C5: 10703347 | D5: =B5-C5 -> 26637573 | E5: =B5*0.25 -> 9335229.9 | F5: =B5*0.1 -> 3734091.9 | G5: =B5*0.15 -> 5601137.9 | H5: =D5/B5 -> 0.71336146
A6: 45175 | B6: 37244792 | C6: 12600903 | D6: =B6-C6 -> 24643889 | E6: =B6*0.25 -> 9311198.1 | F6: =B6*0.1 -> 3724479.2 | G6: =B6*0.15 -> 5586718.9 | H6: =D6/B6 -> 0.66167343
A7: 45177 | B7: 36440413 | C7: 12956000 | D7: =B7-C7 -> 23484413 | E7: =B7*0.25 -> 9110103.2 | F7: =B7*0.1 -> 3644041.3 | G7: =B7*0.15 -> 5466061.9 | H7: =D7/B7 -> 0.64446068
A8: 45178 | B8: 36613715 | C8: 12904681 | D8: =B8-C8 -> 23709034 | E8: =B8*0.25 -> 9153428.8 | F8: =B8*0.1 -> 3661371.5 | G8: =B8*0.15 -> 5492057.2 | H8: =D8/B8 -> 0.64754516
A9: 45180 | B9: 36586860 | C9: 12904102 | D9: =B9-C9 -> 23682758 | E9: =B9*0.25 -> 9146714.9 | F9: =B9*0.1 -> 3658686 | G9: =B9*0.15 -> 5488028.9 | H9: =D9/B9 -> 0.64730229
A10: 45181 | B10: 37262904 | C10: 14578535 | D10: =B10-C10 -> 22684369 | E10: =B10*0.25 -> 9315725.9 | F10: =B10*0.1 -> 3726290.4 | G10: =B10*0.15 -> 5589435.6 | H10: =D10/B10 -> 0.60876545
A11: 45182 | B11: 36597913 | C11: 14489723 | D11: =B11-C11 -> 22108190 | E11: =B11*0.25 -> 9149478.2 | F11: =B11*0.1 -> 3659791.3 | G11: =B11*0.15 -> 5489687 | H11: =D11/B11 -> 0.60408335
A12: 45183 | B12: 36912497 | C12: 14552983 | D12: =B12-C12 -> 22359514 | E12: =B12*0.25 -> 9228124.2 | F12: =B12*0.1 -> 3691249.7 | G12: =B12*0.15 -> 5536874.5 | H12: =D12/B12 -> 0.60574374
A13: 45184 | B13: 37474543 | C13: 14681211 | D13: =B13-C13 -> 22793332 | E13: =B13*0.25 -> 9368635.8 | F13: =B13*0.1 -> 3747454.3 | G13: =B13*0.15 -> 5621181.5 | H13: =D13/B13 -> 0.60823509
